Traceback (most recent call last):
  File "/usr/local/python/3.12.1/lib/python3.12/site-packages/jupyter_cache/executors/utils.py", line 58, in single_nb_execution
    executenb(
  File "/home/codespace/.local/lib/python3.12/site-packages/nbclient/client.py", line 1319, in execute
    return NotebookClient(nb=nb, resources=resources, km=km, **kwargs).execute()
           ^^^^^^^^^^^^^^^^^^^^^^^^^^^^^^^^^^^^^^^^^^^^^^^^^^^^^^^^^^^^^^^^^^^^^
  File "/home/codespace/.local/lib/python3.12/site-packages/jupyter_core/utils/__init__.py", line 165, in wrapped
    return loop.run_until_complete(inner)
           ^^^^^^^^^^^^^^^^^^^^^^^^^^^^^^
  File "/usr/local/python/3.12.1/lib/python3.12/asyncio/base_events.py", line 684, in run_until_complete
    return future.result()
           ^^^^^^^^^^^^^^^
  File "/home/codespace/.local/lib/python3.12/site-packages/nbclient/client.py", line 709, in async_execute
    await self.async_execute_cell(
  File "/home/codespace/.local/lib/python3.12/site-packages/nbclient/client.py", line 1062, in async_execute_cell
    await self._check_raise_for_error(cell, cell_index, exec_reply)
  File "/home/codespace/.local/lib/python3.12/site-packages/nbclient/client.py", line 918, in _check_raise_for_error
    raise CellExecutionError.from_cell_and_msg(cell, exec_reply_content)
nbclient.exceptions.CellExecutionError: An error occurred while executing the following cell:
------------------
import pymysql

# Koneksi ke MySQL
mysql_conn = pymysql.connect(
    host="mysql-ab9f2e5-pendata-d.h.aivencloud.com",
    user="avnadmin",
    password="AVNS_iraqnLcleYqP_JZOqhA",
    database="defaultdb",
    port=24202,
    ssl={"ssl": {}}
)
mysql_cur = mysql_conn.cursor()

# Eksekusi query untuk mengambil data dari MySQL
query_mysql = "SELECT * FROM pendatmysql"
mysql_cur.execute(query_mysql)
data_mysql = mysql_cur.fetchall()

# Menampilkan data dari MySQL
print("DATA SQL")
for row in data_mysql:
    print(row)

# Tutup kursor dan koneksi
mysql_cur.close()
mysql_conn.close()
------------------


[31m---------------------------------------------------------------------------[39m
[31mModuleNotFoundError[39m                       Traceback (most recent call last)
[36mCell[39m[36m [39m[32mIn[1][39m[32m, line 1[39m
[32m----> [39m[32m1[39m [38;5;28;01mimport[39;00m[38;5;250m [39m[34;01mpymysql[39;00m
[32m      3[39m [38;5;66;03m# Koneksi ke MySQL[39;00m
[32m      4[39m mysql_conn = pymysql.connect(
[32m      5[39m     host=[33m"[39m[33mmysql-ab9f2e5-pendata-d.h.aivencloud.com[39m[33m"[39m,
[32m      6[39m     user=[33m"[39m[33mavnadmin[39m[33m"[39m,
[32m   (...)[39m[32m     10[39m     ssl={[33m"[39m[33mssl[39m[33m"[39m: {}}
[32m     11[39m )

[31mModuleNotFoundError[39m: No module named 'pymysql'

