Traceback (most recent call last):
  File "/usr/local/python/3.12.1/lib/python3.12/site-packages/jupyter_cache/executors/utils.py", line 58, in single_nb_execution
    executenb(
  File "/home/codespace/.local/lib/python3.12/site-packages/nbclient/client.py", line 1314, in execute
    return NotebookClient(nb=nb, resources=resources, km=km, **kwargs).execute()
           ^^^^^^^^^^^^^^^^^^^^^^^^^^^^^^^^^^^^^^^^^^^^^^^^^^^^^^^^^^^^^^^^^^^^^
  File "/home/codespace/.local/lib/python3.12/site-packages/jupyter_core/utils/__init__.py", line 165, in wrapped
    return loop.run_until_complete(inner)
           ^^^^^^^^^^^^^^^^^^^^^^^^^^^^^^
  File "/usr/local/python/3.12.1/lib/python3.12/asyncio/base_events.py", line 684, in run_until_complete
    return future.result()
           ^^^^^^^^^^^^^^^
  File "/home/codespace/.local/lib/python3.12/site-packages/nbclient/client.py", line 709, in async_execute
    await self.async_execute_cell(
  File "/home/codespace/.local/lib/python3.12/site-packages/nbclient/client.py", line 1062, in async_execute_cell
    await self._check_raise_for_error(cell, cell_index, exec_reply)
  File "/home/codespace/.local/lib/python3.12/site-packages/nbclient/client.py", line 918, in _check_raise_for_error
    raise CellExecutionError.from_cell_and_msg(cell, exec_reply_content)
nbclient.exceptions.CellExecutionError: An error occurred while executing the following cell:
------------------
import pymysql

# Koneksi ke MySQL
mysql_conn = pymysql.connect(
    host="mysql-ab9f2e5-pendata-d.h.aivencloud.com",
    user="avnadmin",
    password="AVNS_iraqnLcleYqP_JZOqhA",
    database="defaultdb",
    port=24202,
    ssl={"ssl": {}}
)
mysql_cur = mysql_conn.cursor()

# Eksekusi query untuk mengambil data dari MySQL
query_mysql = "SELECT * FROM pendatmysql"
mysql_cur.execute(query_mysql)
data_mysql = mysql_cur.fetchall()

# Menampilkan data dari MySQL
print("DATA SQL")
for row in data_mysql:
    print(row)

# Tutup kursor dan koneksi
mysql_cur.close()
mysql_conn.close()
------------------


[0;31m---------------------------------------------------------------------------[0m
[0;31mModuleNotFoundError[0m                       Traceback (most recent call last)
Cell [0;32mIn[1], line 1[0m
[0;32m----> 1[0m [38;5;28;01mimport[39;00m [38;5;21;01mpymysql[39;00m
[1;32m      3[0m [38;5;66;03m# Koneksi ke MySQL[39;00m
[1;32m      4[0m mysql_conn [38;5;241m=[39m pymysql[38;5;241m.[39mconnect(
[1;32m      5[0m     host[38;5;241m=[39m[38;5;124m"[39m[38;5;124mmysql-ab9f2e5-pendata-d.h.aivencloud.com[39m[38;5;124m"[39m,
[1;32m      6[0m     user[38;5;241m=[39m[38;5;124m"[39m[38;5;124mavnadmin[39m[38;5;124m"[39m,
[0;32m   (...)[0m
[1;32m     10[0m     ssl[38;5;241m=[39m{[38;5;124m"[39m[38;5;124mssl[39m[38;5;124m"[39m: {}}
[1;32m     11[0m )

[0;31mModuleNotFoundError[0m: No module named 'pymysql'

